Traceback (most recent call last):
  File "/home/lima/.local/lib/python3.11/site-packages/requests/models.py", line 971, in json
Traceback (most recent call last):
  File "/home/lima/.local/lib/python3.11/site-packages/requests/models.py", line 971, in json
    return complexjson.loads(self.text, **kwargs)
    return complexjson.loads(self.text, **kwargs)
           ^^^^^^^^^^^^^^^^^^^^^^^^^^^^^^^^^^^^^^
  File "/home/lima/.asdf/installs/python/anaconda3-2023.07-2/lib/python3.11/json/__init__.py", line 346, in loads
           ^^^^^^^^^^^^^^^^^^^^^^^^^^^^^^^^^^^^^^
  File "/home/lima/.asdf/installs/python/anaconda3-2023.07-2/lib/python3.11/json/__init__.py", line 346, in loads
    return _default_decoder.decode(s)
    return _default_decoder.decode(s)
           ^^^^^^^^^^^^^^^^^^^^^^^^^^
  File "/home/lima/.asdf/installs/python/anaconda3-2023.07-2/lib/python3.11/json/decoder.py", line 337, in decode
           ^^^^^^^^^^^^^^^^^^^^^^^^^^
  File "/home/lima/.asdf/installs/python/anaconda3-2023.07-2/lib/python3.11/json/decoder.py", line 337, in decode
    obj, end = self.raw_decode(s, idx=_w(s, 0).end())
    obj, end = self.raw_decode(s, idx=_w(s, 0).end())
               ^^^^^^^^^^^^^^^^^^^^^^^^^^^^^^^^^^^^^^
  File "/home/lima/.asdf/installs/python/anaconda3-2023.07-2/lib/python3.11/json/decoder.py", line 355, in raw_decode
               ^^^^^^^^^^^^^^^^^^^^^^^^^^^^^^^^^^^^^^
  File "/home/lima/.asdf/installs/python/anaconda3-2023.07-2/lib/python3.11/json/decoder.py", line 355, in raw_decode
    raise JSONDecodeError("Expecting value", s, err.value) from None
    raise JSONDecodeError("Expecting value", s, err.value) from None
json.decoder.JSONDecodeError: Expecting value: line 1 column 1 (char 0)

During handling of the above exception, another exception occurred:

Traceback (most recent call last):
  File "/home/lima/university/FEUP-PRI/project/src/get_top_tracks.py", line 299, in <module>
json.decoder.JSONDecodeError: Expecting value: line 1 column 1 (char 0)

During handling of the above exception, another exception occurred:

Traceback (most recent call last):
  File "/home/lima/university/FEUP-PRI/project/src/get_top_tracks.py", line 299, in <module>
    visit_track(next_track)
    visit_track(next_track)
  File "/home/lima/university/FEUP-PRI/project/src/get_top_tracks.py", line 212, in visit_track
  File "/home/lima/university/FEUP-PRI/project/src/get_top_tracks.py", line 212, in visit_track
    res = get_from_lastfm('track.getInfo', artist=artist, track=track_name)
    res = get_from_lastfm('track.getInfo', artist=artist, track=track_name)
          ^^^^^^^^^^^^^^^^^^^^^^^^^^^^^^^^^^^^^^^^^^^^^^^^^^^^^^^^^^^^^^^^^
          ^^^^^^^^^^^^^^^^^^^^^^^^^^^^^^^^^^^^^^^^^^^^^^^^^^^^^^^^^^^^^^^^^
  File "/home/lima/university/FEUP-PRI/project/src/get_top_tracks.py", line 83, in get_from_lastfm
  File "/home/lima/university/FEUP-PRI/project/src/get_top_tracks.py", line 83, in get_from_lastfm
    return response.json()
    return response.json()
           ^^^^^^^^^^^^^^^
  File "/home/lima/.local/lib/python3.11/site-packages/requests/models.py", line 975, in json
           ^^^^^^^^^^^^^^^
  File "/home/lima/.local/lib/python3.11/site-packages/requests/models.py", line 975, in json
    raise RequestsJSONDecodeError(e.msg, e.doc, e.pos)
requests.exceptions.JSONDecodeError: Expecting value: line 1 column 1 (char 0)
    raise RequestsJSONDecodeError(e.msg, e.doc, e.pos)
requests.exceptions.JSONDecodeError: Expecting value: line 1 column 1 (char 0)
