Traceback (most recent call last):
  File "/home/lima/.local/lib/python3.11/site-packages/urllib3/connection.py", line 203, in _new_conn
Traceback (most recent call last):
  File "/home/lima/.local/lib/python3.11/site-packages/urllib3/connection.py", line 203, in _new_conn
    sock = connection.create_connection(
           ^^^^^^^^^^^^^^^^^^^^^^^^^^^^^
  File "/home/lima/.local/lib/python3.11/site-packages/urllib3/util/connection.py", line 60, in create_connection
    sock = connection.create_connection(
           ^^^^^^^^^^^^^^^^^^^^^^^^^^^^^
  File "/home/lima/.local/lib/python3.11/site-packages/urllib3/util/connection.py", line 60, in create_connection
    for res in socket.getaddrinfo(host, port, family, socket.SOCK_STREAM):
    for res in socket.getaddrinfo(host, port, family, socket.SOCK_STREAM):
               ^^^^^^^^^^^^^^^^^^^^^^^^^^^^^^^^^^^^^^^^^^^^^^^^^^^^^^^^^^
               ^^^^^^^^^^^^^^^^^^^^^^^^^^^^^^^^^^^^^^^^^^^^^^^^^^^^^^^^^^
  File "/home/lima/.asdf/installs/python/anaconda3-2023.07-2/lib/python3.11/socket.py", line 962, in getaddrinfo
  File "/home/lima/.asdf/installs/python/anaconda3-2023.07-2/lib/python3.11/socket.py", line 962, in getaddrinfo
    for res in _socket.getaddrinfo(host, port, family, type, proto, flags):
    for res in _socket.getaddrinfo(host, port, family, type, proto, flags):
               ^^^^^^^^^^^^^^^^^^^^^^^^^^^^^^^^^^^^^^^^^^^^^^^^^^^^^^^^^^^
socket.gaierror: [Errno -2] Name or service not known
               ^^^^^^^^^^^^^^^^^^^^^^^^^^^^^^^^^^^^^^^^^^^^^^^^^^^^^^^^^^^
socket.gaierror: [Errno -2] Name or service not known

The above exception was the direct cause of the following exception:

Traceback (most recent call last):

The above exception was the direct cause of the following exception:

Traceback (most recent call last):
  File "/home/lima/.local/lib/python3.11/site-packages/urllib3/connectionpool.py", line 790, in urlopen
  File "/home/lima/.local/lib/python3.11/site-packages/urllib3/connectionpool.py", line 790, in urlopen
    response = self._make_request(
               ^^^^^^^^^^^^^^^^^^^
  File "/home/lima/.local/lib/python3.11/site-packages/urllib3/connectionpool.py", line 496, in _make_request
    response = self._make_request(
               ^^^^^^^^^^^^^^^^^^^
  File "/home/lima/.local/lib/python3.11/site-packages/urllib3/connectionpool.py", line 496, in _make_request
    conn.request(
  File "/home/lima/.local/lib/python3.11/site-packages/urllib3/connection.py", line 395, in request
    conn.request(
  File "/home/lima/.local/lib/python3.11/site-packages/urllib3/connection.py", line 395, in request
    self.endheaders()
  File "/home/lima/.asdf/installs/python/anaconda3-2023.07-2/lib/python3.11/http/client.py", line 1281, in endheaders
    self.endheaders()
  File "/home/lima/.asdf/installs/python/anaconda3-2023.07-2/lib/python3.11/http/client.py", line 1281, in endheaders
    self._send_output(message_body, encode_chunked=encode_chunked)
  File "/home/lima/.asdf/installs/python/anaconda3-2023.07-2/lib/python3.11/http/client.py", line 1041, in _send_output
    self._send_output(message_body, encode_chunked=encode_chunked)
  File "/home/lima/.asdf/installs/python/anaconda3-2023.07-2/lib/python3.11/http/client.py", line 1041, in _send_output
    self.send(msg)
  File "/home/lima/.asdf/installs/python/anaconda3-2023.07-2/lib/python3.11/http/client.py", line 979, in send
    self.send(msg)
  File "/home/lima/.asdf/installs/python/anaconda3-2023.07-2/lib/python3.11/http/client.py", line 979, in send
    self.connect()
  File "/home/lima/.local/lib/python3.11/site-packages/urllib3/connection.py", line 243, in connect
    self.connect()
  File "/home/lima/.local/lib/python3.11/site-packages/urllib3/connection.py", line 243, in connect
    self.sock = self._new_conn()
                ^^^^^^^^^^^^^^^^
  File "/home/lima/.local/lib/python3.11/site-packages/urllib3/connection.py", line 210, in _new_conn
    self.sock = self._new_conn()
                ^^^^^^^^^^^^^^^^
  File "/home/lima/.local/lib/python3.11/site-packages/urllib3/connection.py", line 210, in _new_conn
    raise NameResolutionError(self.host, self, e) from e
    raise NameResolutionError(self.host, self, e) from e
urllib3.exceptions.NameResolutionError: <urllib3.connection.HTTPConnection object at 0x7f359a9f2810>: Failed to resolve 'ws.audioscrobbler.com' ([Errno -2] Name or service not known)

The above exception was the direct cause of the following exception:

Traceback (most recent call last):
urllib3.exceptions.NameResolutionError: <urllib3.connection.HTTPConnection object at 0x7f359a9f2810>: Failed to resolve 'ws.audioscrobbler.com' ([Errno -2] Name or service not known)

The above exception was the direct cause of the following exception:

Traceback (most recent call last):
  File "/home/lima/.local/lib/python3.11/site-packages/requests/adapters.py", line 486, in send
  File "/home/lima/.local/lib/python3.11/site-packages/requests/adapters.py", line 486, in send
    resp = conn.urlopen(
           ^^^^^^^^^^^^^
  File "/home/lima/.local/lib/python3.11/site-packages/urllib3/connectionpool.py", line 844, in urlopen
    resp = conn.urlopen(
           ^^^^^^^^^^^^^
  File "/home/lima/.local/lib/python3.11/site-packages/urllib3/connectionpool.py", line 844, in urlopen
    retries = retries.increment(
              ^^^^^^^^^^^^^^^^^^
  File "/home/lima/.local/lib/python3.11/site-packages/urllib3/util/retry.py", line 515, in increment
    retries = retries.increment(
              ^^^^^^^^^^^^^^^^^^
  File "/home/lima/.local/lib/python3.11/site-packages/urllib3/util/retry.py", line 515, in increment
    raise MaxRetryError(_pool, url, reason) from reason  # type: ignore[arg-type]
    raise MaxRetryError(_pool, url, reason) from reason  # type: ignore[arg-type]
    ^^^^^^^^^^^^^^^^^^^^^^^^^^^^^^^^^^^^^^^^^^^^^^^^^^^
urllib3.exceptions.MaxRetryError: HTTPConnectionPool(host='ws.audioscrobbler.com', port=80): Max retries exceeded with url: /2.0/?artist=MF+DOOM&track=Vomitspit&api_key=d706fd0c0aef8a6ae8edad11ea7a82d4&format=json&method=track.getInfo (Caused by NameResolutionError("<urllib3.connection.HTTPConnection object at 0x7f359a9f2810>: Failed to resolve 'ws.audioscrobbler.com' ([Errno -2] Name or service not known)"))

During handling of the above exception, another exception occurred:

Traceback (most recent call last):
    ^^^^^^^^^^^^^^^^^^^^^^^^^^^^^^^^^^^^^^^^^^^^^^^^^^^
urllib3.exceptions.MaxRetryError: HTTPConnectionPool(host='ws.audioscrobbler.com', port=80): Max retries exceeded with url: /2.0/?artist=MF+DOOM&track=Vomitspit&api_key=d706fd0c0aef8a6ae8edad11ea7a82d4&format=json&method=track.getInfo (Caused by NameResolutionError("<urllib3.connection.HTTPConnection object at 0x7f359a9f2810>: Failed to resolve 'ws.audioscrobbler.com' ([Errno -2] Name or service not known)"))

During handling of the above exception, another exception occurred:

Traceback (most recent call last):
  File "/home/lima/university/FEUP-PRI/project/src/get_top_tracks.py", line 284, in <module>
  File "/home/lima/university/FEUP-PRI/project/src/get_top_tracks.py", line 284, in <module>
    visit_track(next_track)
  File "/home/lima/university/FEUP-PRI/project/src/get_top_tracks.py", line 199, in visit_track
    visit_track(next_track)
  File "/home/lima/university/FEUP-PRI/project/src/get_top_tracks.py", line 199, in visit_track
    res = get_from_lastfm('track.getInfo', artist=artist, track=track_name)
    res = get_from_lastfm('track.getInfo', artist=artist, track=track_name)
          ^^^^^^^^^^^^^^^^^^^^^^^^^^^^^^^^^^^^^^^^^^^^^^^^^^^^^^^^^^^^^^^^^
  File "/home/lima/university/FEUP-PRI/project/src/get_top_tracks.py", line 70, in get_from_lastfm
          ^^^^^^^^^^^^^^^^^^^^^^^^^^^^^^^^^^^^^^^^^^^^^^^^^^^^^^^^^^^^^^^^^
  File "/home/lima/university/FEUP-PRI/project/src/get_top_tracks.py", line 70, in get_from_lastfm
    response = requests.get(f'http://ws.audioscrobbler.com/2.0/', params=kwargs)
    response = requests.get(f'http://ws.audioscrobbler.com/2.0/', params=kwargs)
               ^^^^^^^^^^^^^^^^^^^^^^^^^^^^^^^^^^^^^^^^^^^^^^^^^^^^^^^^^^^^^^^^^
  File "/home/lima/.local/lib/python3.11/site-packages/requests/api.py", line 73, in get
               ^^^^^^^^^^^^^^^^^^^^^^^^^^^^^^^^^^^^^^^^^^^^^^^^^^^^^^^^^^^^^^^^^
  File "/home/lima/.local/lib/python3.11/site-packages/requests/api.py", line 73, in get
    return request("get", url, params=params, **kwargs)
    return request("get", url, params=params, **kwargs)
           ^^^^^^^^^^^^^^^^^^^^^^^^^^^^^^^^^^^^^^^^^^^^
  File "/home/lima/.local/lib/python3.11/site-packages/requests/api.py", line 59, in request
           ^^^^^^^^^^^^^^^^^^^^^^^^^^^^^^^^^^^^^^^^^^^^
  File "/home/lima/.local/lib/python3.11/site-packages/requests/api.py", line 59, in request
    return session.request(method=method, url=url, **kwargs)
    return session.request(method=method, url=url, **kwargs)
           ^^^^^^^^^^^^^^^^^^^^^^^^^^^^^^^^^^^^^^^^^^^^^^^^^
  File "/home/lima/.local/lib/python3.11/site-packages/requests/sessions.py", line 589, in request
           ^^^^^^^^^^^^^^^^^^^^^^^^^^^^^^^^^^^^^^^^^^^^^^^^^
  File "/home/lima/.local/lib/python3.11/site-packages/requests/sessions.py", line 589, in request
    resp = self.send(prep, **send_kwargs)
    resp = self.send(prep, **send_kwargs)
           ^^^^^^^^^^^^^^^^^^^^^^^^^^^^^^
  File "/home/lima/.local/lib/python3.11/site-packages/requests/sessions.py", line 703, in send
           ^^^^^^^^^^^^^^^^^^^^^^^^^^^^^^
  File "/home/lima/.local/lib/python3.11/site-packages/requests/sessions.py", line 703, in send
    r = adapter.send(request, **kwargs)
    r = adapter.send(request, **kwargs)
        ^^^^^^^^^^^^^^^^^^^^^^^^^^^^^^^
  File "/home/lima/.local/lib/python3.11/site-packages/requests/adapters.py", line 519, in send
        ^^^^^^^^^^^^^^^^^^^^^^^^^^^^^^^
  File "/home/lima/.local/lib/python3.11/site-packages/requests/adapters.py", line 519, in send
    raise ConnectionError(e, request=request)
    raise ConnectionError(e, request=request)
requests.exceptions.ConnectionError: HTTPConnectionPool(host='ws.audioscrobbler.com', port=80): Max retries exceeded with url: /2.0/?artist=MF+DOOM&track=Vomitspit&api_key=d706fd0c0aef8a6ae8edad11ea7a82d4&format=json&method=track.getInfo (Caused by NameResolutionError("<urllib3.connection.HTTPConnection object at 0x7f359a9f2810>: Failed to resolve 'ws.audioscrobbler.com' ([Errno -2] Name or service not known)"))
requests.exceptions.ConnectionError: HTTPConnectionPool(host='ws.audioscrobbler.com', port=80): Max retries exceeded with url: /2.0/?artist=MF+DOOM&track=Vomitspit&api_key=d706fd0c0aef8a6ae8edad11ea7a82d4&format=json&method=track.getInfo (Caused by NameResolutionError("<urllib3.connection.HTTPConnection object at 0x7f359a9f2810>: Failed to resolve 'ws.audioscrobbler.com' ([Errno -2] Name or service not known)"))
